<?xml version="1.0" ?>
<!-- =================================================================================== -->
<!-- |    This document was autogenerated by xacro from smartcar.urdf.xacro            | -->
<!-- |    EDITING THIS FILE BY HAND IS NOT RECOMMENDED                                 | -->
<!-- =================================================================================== -->
<robot name="smart_car">
  <!-- ======================== Materials ========================= -->
  <material name="gray">
    <color rgba="0.6 0.6 0.6 1"/>
  </material>
  <material name="black">
    <color rgba="0.1 0.1 0.1 1"/>
  </material>

  <!-- ======================== Base links ======================== -->
  <link name="base_footprint"/>
  <joint name="base_footprint_to_base_link" type="fixed">
    <origin rpy="0 0 0" xyz="0 0 0.032"/>
    <parent link="base_footprint"/>
    <child link="base_link"/>
  </joint>
  <link name="base_link"/>

  <link name="chassis_link">
    <visual>
      <geometry>
        <box size="0.257 0.14500000000000002 0.03"/>
      </geometry>
      <material name="gray"/>
    </visual>
    <collision>
      <geometry>
        <box size="0.257 0.14500000000000002 0.03"/>
      </geometry>
    </collision>
    <inertial>
      <mass value="2.0"/>
      <origin rpy="0 0 0" xyz="0 0 0"/>
      <inertia ixx="0.003654166666666668" ixy="0" ixz="0" iyy="0.011158166666666665" iyz="0" izz="0.014512333333333334"/>
    </inertial>
  </link>
  <joint name="chassis_fixed" type="fixed">
    <origin rpy="0 0 0" xyz="0 0 0"/>
    <parent link="base_link"/>
    <child link="chassis_link"/>
  </joint>

  <!-- ==================== Wheels ==================== -->
  <link name="back_left_wheel_link">
    <visual>
      <geometry>
        <cylinder length="0.025" radius="0.032"/>
      </geometry>
      <origin rpy="1.5708 0 0"/>
      <material name="black"/>
    </visual>
    <collision>
      <geometry>
        <cylinder length="0.025" radius="0.032"/>
      </geometry>
      <origin rpy="1.5708 0 0"/>
    </collision>
    <inertial>
      <mass value="0.3"/>
      <origin rpy="0 0 0" xyz="0 0 0"/>
      <inertia ixx="9.2425e-05" ixy="0" ixz="0" iyy="9.2425e-05" iyz="0" izz="0.0001536"/>
    </inertial>
  </link>
  <joint name="back_left_wheel_joint" type="continuous">
    <parent link="chassis_link"/>
    <child link="back_left_wheel_link"/>
    <origin xyz="-0.1285 0.085 0"/>
    <axis xyz="0 1 0"/>
  </joint>

  <link name="back_right_wheel_link">
    <visual>
      <geometry>
        <cylinder length="0.025" radius="0.032"/>
      </geometry>
      <origin rpy="1.5708 0 0"/>
      <material name="black"/>
    </visual>
    <collision>
      <geometry>
        <cylinder length="0.025" radius="0.032"/>
      </geometry>
      <origin rpy="1.5708 0 0"/>
    </collision>
    <inertial>
      <mass value="0.3"/>
      <origin rpy="0 0 0" xyz="0 0 0"/>
      <inertia ixx="9.2425e-05" ixy="0" ixz="0" iyy="9.2425e-05" iyz="0" izz="0.0001536"/>
    </inertial>
  </link>
  <joint name="back_right_wheel_joint" type="continuous">
    <parent link="chassis_link"/>
    <child link="back_right_wheel_link"/>
    <origin xyz="-0.1285 -0.085 0"/>
    <axis xyz="0 1 0"/>
  </joint>

  <link name="front_left_steer_link">
    <visual>
      <geometry>
        <cylinder length="0.04" radius="0.01"/>
      </geometry>
      <origin rpy="1.5708 0 0"/>
      <material name="gray"/>
    </visual>
    <collision>
      <geometry>
        <cylinder length="0.04" radius="0.01"/>
      </geometry>
      <origin rpy="1.5708 0 0"/>
    </collision>
    <inertial>
      <mass value="0.05"/>
      <origin rpy="0 0 0" xyz="0 0 0"/>
      <inertia ixx="7.916666666666667e-06" ixy="0" ixz="0" iyy="7.916666666666667e-06" iyz="0" izz="2.5e-06"/>
    </inertial>
  </link>
  <joint name="front_left_wheel_steer_joint" type="continuous">
    <parent link="chassis_link"/>
    <child link="front_left_steer_link"/>
    <origin xyz="0.1285 0.085 0"/>
    <axis xyz="0 0 1"/>
  </joint>

  <link name="front_left_wheel_link">
    <visual>
      <geometry>
        <cylinder length="0.025" radius="0.032"/>
      </geometry>
      <origin rpy="1.5708 0 0"/>
      <material name="black"/>
    </visual>
    <collision>
      <geometry>
        <cylinder length="0.025" radius="0.032"/>
      </geometry>
      <origin rpy="1.5708 0 0"/>
    </collision>
    <inertial>
      <mass value="0.3"/>
      <origin rpy="0 0 0" xyz="0 0 0"/>
      <inertia ixx="9.2425e-05" ixy="0" ixz="0" iyy="9.2425e-05" iyz="0" izz="0.0001536"/>
    </inertial>
  </link>
  <joint name="front_left_wheel_joint" type="continuous">
    <parent link="front_left_steer_link"/>
    <child link="front_left_wheel_link"/>
    <axis xyz="0 1 0"/>
  </joint>

  <link name="front_right_steer_link">
    <visual>
      <geometry>
        <cylinder length="0.04" radius="0.01"/>
      </geometry>
      <origin rpy="1.5708 0 0"/>
      <material name="gray"/>
    </visual>
    <collision>
      <geometry>
        <cylinder length="0.04" radius="0.01"/>
      </geometry>
      <origin rpy="1.5708 0 0"/>
    </collision>
    <inertial>
      <mass value="0.05"/>
      <origin rpy="0 0 0" xyz="0 0 0"/>
      <inertia ixx="7.916666666666667e-06" ixy="0" ixz="0" iyy="7.916666666666667e-06" iyz="0" izz="2.5e-06"/>
    </inertial>
  </link>
  <joint name="front_right_wheel_steer_joint" type="continuous">
    <parent link="chassis_link"/>
    <child link="front_right_steer_link"/>
    <origin xyz="0.1285 -0.085 0"/>
    <axis xyz="0 0 1"/>
  </joint>

  <link name="front_right_wheel_link">
    <visual>
      <geometry>
        <cylinder length="0.025" radius="0.032"/>
      </geometry>
      <origin rpy="1.5708 0 0"/>
      <material name="black"/>
    </visual>
    <collision>
      <geometry>
        <cylinder length="0.025" radius="0.032"/>
      </geometry>
      <origin rpy="1.5708 0 0"/>
    </collision>
    <inertial>
      <mass value="0.3"/>
      <origin rpy="0 0 0" xyz="0 0 0"/>
      <inertia ixx="9.2425e-05" ixy="0" ixz="0" iyy="9.2425e-05" iyz="0" izz="0.0001536"/>
    </inertial>
  </link>
  <joint name="front_right_wheel_joint" type="continuous">
    <parent link="front_right_steer_link"/>
    <child link="front_right_wheel_link"/>
    <axis xyz="0 1 0"/>
  </joint>

  <!-- =========================== IMU ============================ -->
  <link name="imu_link">
    <visual>
      <geometry>
        <box size="0.02 0.02 0.02"/>
      </geometry>
      <origin rpy="0 0 0" xyz="0 0 0"/>
      <material name="gray"/>
    </visual>
    <collision>
      <geometry>
        <box size="0.02 0.02 0.02"/>
      </geometry>
      <origin rpy="0 0 0" xyz="0 0 0"/>
    </collision>
    <inertial>
      <mass value="0.01"/>
      <origin rpy="0 0 0" xyz="0 0 0"/>
      <inertia ixx="4.1666667e-07" ixy="0" ixz="0" iyy="4.1666667e-07" iyz="0" izz="6.6666667e-07"/>
    </inertial>
  </link>
  <joint name="imu_fixed_joint" type="fixed">
    <origin rpy="0 0 0" xyz="0 0 0"/>
    <parent link="chassis_link"/>
    <child link="imu_link"/>
  </joint>

  <gazebo reference="imu_link">
    <sensor name="imu_sensor" type="imu">
      <always_on>true</always_on>
      <update_rate>100</update_rate>
      <visualize>false</visualize>
      <plugin filename="libgazebo_ros_imu_sensor.so" name="imu_plugin">
        <ros>
          <namespace>/</namespace>
          <remapping>~/out:=/imu_data</remapping>
        </ros>
        <initial_orientation_as_reference>false</initial_orientation_as_reference>
      </plugin>
    </sensor>
  </gazebo>

  <!-- ====================== LIDAR ====================== -->
<link name="sllidar_base_link">
  <visual>
    <geometry>
      <cylinder length="0.02" radius="0.03"/>
    </geometry>
    <!-- Rotate cylinder 90° around Z so it looks flat on top -->
    <origin xyz="0 0 0" rpy="0 0 1.5708"/>
    <material name="black"/>
  </visual>
  <collision>
    <geometry>
      <cylinder length="0.02" radius="0.03"/>
    </geometry>
    <origin xyz="0 0 0" rpy="0 0 1.5708"/>
  </collision>
  <inertial>
    <mass value="0.15"/>
    <origin xyz="0 0 0" rpy="0 0 0"/>
    <inertia ixx="3.875e-05" ixy="0" ixz="0" iyy="3.875e-05" iyz="0" izz="6.75e-05"/>
  </inertial>
</link>

<joint name="sllidar_mount_joint" type="fixed">
  <!-- put it above the chassis, facing forward -->
  <origin xyz="0.1285 0 0.10" rpy="0 0 0"/>
  <parent link="base_link"/>
  <child link="sllidar_base_link"/>
</joint>

<gazebo reference="sllidar_base_link">
  <sensor name="front_laser" type="ray">
    <always_on>true</always_on>
    <update_rate>15</update_rate>
    <visualize>true</visualize>
    <!-- this time no rotation needed -->
    <pose>0 0 0 0 0 0</pose>
    <ray>
      <scan>
        <horizontal>
          <samples>720</samples>
          <resolution>1</resolution>
          <min_angle>-1.13446</min_angle> <!-- ~130° FOV -->
          <max_angle>1.13446</max_angle>
        </horizontal>
      </scan>
      <range>
        <min>0.12</min>
        <max>12.0</max>
        <resolution>0.01</resolution>
      </range>
      <noise type="gaussian">
        <mean>0.0</mean>
        <stddev>0.01</stddev>
      </noise>
    </ray>
    <plugin filename="libgazebo_ros_ray_sensor.so" name="gazebo_ros_ray_sensor">
      <ros>
        <namespace>/</namespace>
        <remapping>~/out:=/scan</remapping>
      </ros>
      <output_type>sensor_msgs/LaserScan</output_type>
      <frame_name>sllidar_base_link</frame_name>
    </plugin>
  </sensor>
</gazebo>


<!-- ====================== CAR DRIVE PLUGIN ====================== -->
<gazebo>
  <plugin name="car_plugin" filename="libcar_gazebo_plugin.so">
    <ros>
      <namespace>/</namespace>
      <remapping>~/cmd_vel:=/cmd_vel</remapping>
    </ros>
  </plugin>
</gazebo>



</robot>
